<?xml version="1.0" ?>
<robot name="mz04">
    <link name="base_link">
        <visual>
            <origin rpy="0.0 0 0" xyz="0 0 0" />
            <geometry>
                <mesh filename="package://rl_nachi/urdf/mz04/MZ04-01_BASE.dae" />
            </geometry>
        </visual>
        <collision>
            <geometry>
                <mesh filename="package://rl_nachi/urdf/mz04/MZ04-01_BASE.stl" />
            </geometry>
        </collision>
        <!-- <inertial>
            <mass value="0.1" />
            <origin xyz="0 0 0" rpy="0 0 0" />
            <inertia ixx="0.03" iyy="0.03" izz="0.03" ixy="0.0" ixz="0.0" iyz="0.0" />
        </inertial> -->
    </link>
    <link name="J1_link">
        <visual>
            <origin rpy="0.0 0 0" xyz="0 0 -0.340" />
            <geometry>
                <mesh filename="package://rl_nachi/urdf/mz04/MZ04-01_J1.dae" />
            </geometry>
        </visual>
        <collision>
            <geometry>
                <mesh filename="package://rl_nachi/urdf/mz04/MZ04-01_J1.stl" />
            </geometry>
        </collision>
        <inertial>
            <mass value="0.1" />
            <origin xyz="0 0 0" rpy="0 0 0" />
            <inertia ixx="0.03" iyy="0.03" izz="0.03" ixy="0.0" ixz="0.0" iyz="0.0" />
        </inertial>
    </link>
    <joint name="J1_joint" type="revolute">
        <origin rpy="0 0 0" xyz="0 0 0.340" />
        <axis xyz="0 0 1" />
        <limit effort="100.0" lower="-3.14" upper="3.14" velocity="0.5" />
        <parent link="base_link" />
        <child link="J1_link" />
    </joint>
    <link name="J2_link">
        <visual>
            <origin rpy="-1.57079633 0 -1.57079633" xyz="-0.340 0.0 0" />
            <geometry>
                <mesh filename="package://rl_nachi/urdf/mz04/MZ04-01_J2.dae" />
            </geometry>
        </visual>
        <collision>
            <geometry>
                <mesh filename="package://rl_nachi/urdf/mz04/MZ04-01_J2.stl" />
            </geometry>
        </collision>
        <inertial>
            <mass value="0.1" />
            <origin xyz="0 0 0" rpy="0 0 0" />
            <inertia ixx="0.03" iyy="0.03" izz="0.03" ixy="0.0" ixz="0.0" iyz="0.0" />
        </inertial>
    </link>
    <joint name="J2_joint" type="revolute">
        <!--origin rpy="1.57079633 -1.57079633 0" xyz="0.0 0 0.0" /-->
        <origin rpy="1.57079633 0 0" xyz="0.0 0 0.0" />
        <axis xyz="0 0 1" />
        <limit effort="100.0" lower="-3.14" upper="3.14" velocity="0.5" />
        <parent link="J1_link" />
        <child link="J2_link" />
    </joint>
    <link name="J3_link">
        <visual>
            <origin rpy="-1.57079633 0 -1.57079633" xyz="-0.6 0.0 0" />
            <geometry>
                <mesh filename="package://rl_nachi/urdf/mz04/MZ04-01_J3.dae" />
            </geometry>
        </visual>
        <collision>
            <geometry>
                <mesh filename="package://rl_nachi/urdf/mz04/MZ04-01_J3.stl" />
            </geometry>
        </collision>
        <inertial>
            <mass value="0.1" />
            <origin xyz="0 0 0" rpy="0 0 0" />
            <inertia ixx="0.03" iyy="0.03" izz="0.03" ixy="0.0" ixz="0.0" iyz="0.0" />
        </inertial>
    </link>
    <joint name="J3_joint" type="revolute">
        <origin rpy="0 0 0" xyz="0.260 0 0.0" />
        <axis xyz="0 0 1" />
        <limit effort="100.0" lower="-3.14" upper="3.14" velocity="0.5" />
        <parent link="J2_link" />
        <child link="J3_link" />
    </joint>
    <link name="J4_link">
        <visual>
            <origin rpy="0 -1.57079633 3.14159266" xyz="-0.625 0.0 -0.28" />
            <geometry>
                <mesh filename="package://rl_nachi/urdf/mz04/MZ04-01_J4.dae" />
            </geometry>
        </visual>
        <collision>
            <geometry>
                <mesh filename="package://rl_nachi/urdf/mz04/MZ04-01_J4.stl" />
            </geometry>
        </collision>
        <inertial>
            <mass value="0.1" />
            <origin xyz="0 0 0" rpy="0 0 0" />
            <inertia ixx="0.03" iyy="0.03" izz="0.03" ixy="0.0" ixz="0.0" iyz="0.0" />
        </inertial>
    </link>
    <joint name="J4_joint" type="revolute">
        <origin rpy="1.57079633 0 0" xyz="0.025 -0.28 0.0" />
        <axis xyz="0 0 1" />
        <limit effort="100.0" lower="-3.14" upper="3.14" velocity="0.5" />
        <parent link="J3_link" />
        <child link="J4_link" />
    </joint>
    <link name="J5_link">
        <visual>
            <origin rpy="-1.57079633 0 -1.57079633" xyz="-0.625 0.28 -0.0" />
            <geometry>
                <mesh filename="package://rl_nachi/urdf/mz04/MZ04-01_J5.dae" />
            </geometry>
        </visual>
        <collision>
            <geometry>
                <mesh filename="package://rl_nachi/urdf/mz04/MZ04-01_J5.stl" />
            </geometry>
        </collision>
        <inertial>
            <mass value="0.1" />
            <origin xyz="0 0 0" rpy="0 0 0" />
            <inertia ixx="0.03" iyy="0.03" izz="0.03" ixy="0.0" ixz="0.0" iyz="0.0" />
        </inertial>
    </link>
    <joint name="J5_joint" type="revolute">
        <origin rpy="-1.57079633 0 0" xyz="0 0 0" />
        <axis xyz="0 0 1" />
        <limit effort="100.0" lower="-3.14" upper="3.14" velocity="0.5" />
        <parent link="J4_link" />
        <child link="J5_link" />
    </joint>
    <link name="J6_link">
        <visual>
            <origin rpy="0.0 -1.57079633 0" xyz="0.625 0 -0.28" />
            <geometry>
                <mesh filename="package://rl_nachi/urdf/mz04/MZ04-01_J6.dae" />
            </geometry>
        </visual>
        <collision>
            <geometry>
                <mesh filename="package://rl_nachi/urdf/mz04/MZ04-01_J6.stl" />
            </geometry>
        </collision>
        <inertial>
            <mass value="0.1" />
            <origin xyz="0 0 0" rpy="0 0 0" />
            <inertia ixx="0.03" iyy="0.03" izz="0.03" ixy="0.0" ixz="0.0" iyz="0.0" />
        </inertial>
    </link>
    <joint name="J6_joint" type="revolute">
        <origin rpy="1.57079633 0 0" xyz="0.0 0 0.0" />
        <axis xyz="0 0 1" />
        <limit effort="100.0" lower="-3.14" upper="3.14" velocity="0.5" />
        <parent link="J5_link" />
        <child link="J6_link" />
    </joint>


    <link name="flange_link">
        <visual>
            <origin rpy="3.141592 0.0 0" xyz="-0.03 0.03 0.01" />
            <geometry>
                <mesh filename="package://rl_nachi/urdf/mz04/tool.dae" />
            </geometry>
        </visual>
        <collision>
            <geometry>
                <mesh filename="package://rl_nachi/urdf/mz04/tool.stl" />
            </geometry>
        </collision>
        <inertial>
            <mass value="0.1" />
            <origin xyz="0 0 0" rpy="0 0 0" />
            <inertia ixx="0.03" iyy="0.03" izz="0.03" ixy="0.0" ixz="0.0" iyz="0.0" />
        </inertial>
    </link>
    <joint name="flange_joint" type="fixed">
        <origin rpy="0 0 0" xyz="0.0 0 0.072" />
        <parent link="J6_link" />
        <child link="flange_link" />
    </joint>

    <link name="tool_link" />
    <joint name="tool_joint" type="fixed">
        <origin rpy="-3.141592 0 0" xyz="0.085 0 0.049" />
        <parent link="flange_link" />
        <child link="tool_link" />
    </joint>


    <transmission name="trans_J1_joint">
        <type>transmission_interface/SimpleTransmission</type>
        <joint name="J1_joint">
            <hardwareInterface>hardware_interface/PositionJointInterface</hardwareInterface>
        </joint>
        <actuator name="J1_joint_motor">
            <hardwareInterface>hardware_interface/PositionJointInterface</hardwareInterface>
            <mechanicalReduction>1</mechanicalReduction>
        </actuator>
    </transmission>
    <transmission name="trans_J2_joint">
        <type>transmission_interface/SimpleTransmission</type>
        <joint name="J2_joint">
            <hardwareInterface>hardware_interface/PositionJointInterface</hardwareInterface>
        </joint>
        <actuator name="J2_joint_motor">
            <hardwareInterface>hardware_interface/PositionJointInterface</hardwareInterface>
            <mechanicalReduction>1</mechanicalReduction>
        </actuator>
    </transmission>
    <transmission name="trans_J3_joint">
        <type>transmission_interface/SimpleTransmission</type>
        <joint name="J3_joint">
            <hardwareInterface>hardware_interface/PositionJointInterface</hardwareInterface>
        </joint>
        <actuator name="J3_joint_motor">
            <hardwareInterface>hardware_interface/PositionJointInterface</hardwareInterface>
            <mechanicalReduction>1</mechanicalReduction>
        </actuator>
    </transmission>
    <transmission name="trans_J4_joint">
        <type>transmission_interface/SimpleTransmission</type>
        <joint name="J4_joint">
            <hardwareInterface>hardware_interface/PositionJointInterface</hardwareInterface>
        </joint>
        <actuator name="J4_joint_motor">
            <hardwareInterface>hardware_interface/PositionJointInterface</hardwareInterface>
            <mechanicalReduction>1</mechanicalReduction>
        </actuator>
    </transmission>
    <transmission name="trans_J5_joint">
        <type>transmission_interface/SimpleTransmission</type>
        <joint name="J5_joint">
            <hardwareInterface>hardware_interface/PositionJointInterface</hardwareInterface>
        </joint>
        <actuator name="J5_joint_motor">
            <hardwareInterface>hardware_interface/PositionJointInterface</hardwareInterface>
            <mechanicalReduction>1</mechanicalReduction>
        </actuator>
    </transmission>
    <transmission name="trans_J6_joint">
        <type>transmission_interface/SimpleTransmission</type>
        <joint name="J6_joint">
            <hardwareInterface>hardware_interface/PositionJointInterface</hardwareInterface>
        </joint>
        <actuator name="J6_joint_motor">
            <hardwareInterface>hardware_interface/PositionJointInterface</hardwareInterface>
            <mechanicalReduction>1</mechanicalReduction>
        </actuator>
    </transmission>

    <ros2_control name="mz04" type="system">
        <hardware>
            <plugin>nachi_hardware_interface/NachiHardwareInterface</plugin>
            <!-- HardwareInterface制御周期(Hz) -->
            <param name="control_rate">20</param>
            <!-- 起動時の接続有無 0.0以外:起動時に接続を行う 0.0:起動時に接続を行わない -->
            <param name="init_open_id">1.0</param>
        </hardware>
        <joint name="J1_joint">
            <command_interface name="position" />
            <state_interface name="angle" />
            <state_interface name="position" />
            <state_interface name="effort" />
        </joint>
        <joint name="J2_joint">
            <command_interface name="position" />
            <state_interface name="angle" />
            <state_interface name="position" />
            <state_interface name="effort" />
        </joint>
        <joint name="J3_joint">
            <command_interface name="position" />
            <state_interface name="angle" />
            <state_interface name="position" />
            <state_interface name="effort" />
        </joint>
        <joint name="J4_joint">
            <command_interface name="position" />
            <state_interface name="angle" />
            <state_interface name="position" />
            <state_interface name="effort" />
        </joint>
        <joint name="J5_joint">
            <command_interface name="position" />
            <state_interface name="angle" />
            <state_interface name="position" />
            <state_interface name="effort" />
        </joint>
        <joint name="J6_joint">
            <command_interface name="position" />
            <state_interface name="angle" />
            <state_interface name="position" />
            <state_interface name="effort" />
        </joint>
        <joint name="ctrl_move_x_x">
            <command_interface name="position" />
            <state_interface name="angle" />
            <state_interface name="position" />
            <state_interface name="effort" />
        </joint>
        <joint name="ctrl_move_x_y">
            <command_interface name="position" />
            <state_interface name="angle" />
            <state_interface name="position" />
            <state_interface name="effort" />
        </joint>
        <joint name="ctrl_move_x_z">
            <command_interface name="position" />
            <state_interface name="angle" />
            <state_interface name="position" />
            <state_interface name="effort" />
        </joint>
        <joint name="ctrl_move_x_roll">
            <command_interface name="position" />
            <state_interface name="angle" />
            <state_interface name="position" />
            <state_interface name="effort" />
        </joint>
        <joint name="ctrl_move_x_pitch">
            <command_interface name="position" />
            <state_interface name="angle" />
            <state_interface name="position" />
            <state_interface name="effort" />
        </joint>
        <joint name="ctrl_move_x_yaw">
            <command_interface name="position" />
            <state_interface name="angle" />
            <state_interface name="position" />
            <state_interface name="effort" />
        </joint>
        <gpio name="service_command">
            <command_interface name="service" />
        </gpio>
        <gpio name="gpio_start_id">
            <command_interface name="service" />
        </gpio>
        <gpio name="gpio_count_id">
            <command_interface name="service" />
        </gpio>
        <gpio name="setting_signal_1">
            <command_interface name="service" />
        </gpio>
        <gpio name="setting_signal_2">
            <command_interface name="service" />
        </gpio>
        <gpio name="setting_signal_3">
            <command_interface name="service" />
        </gpio>
        <gpio name="setting_signal_4">
            <command_interface name="service" />
        </gpio>
        <gpio name="setting_signal_5">
            <command_interface name="service" />
        </gpio>
        <gpio name="setting_signal_6">
            <command_interface name="service" />
        </gpio>
        <gpio name="setting_signal_7">
            <command_interface name="service" />
        </gpio>
        <gpio name="setting_signal_8">
            <command_interface name="service" />
        </gpio>
        <gpio name="setting_signal_9">
            <command_interface name="service" />
        </gpio>
        <gpio name="setting_signal_10">
            <command_interface name="service" />
        </gpio>
        <gpio name="setting_signal_11">
            <command_interface name="service" />
        </gpio>
        <gpio name="setting_signal_12">
            <command_interface name="service" />
        </gpio>
        <gpio name="setting_signal_13">
            <command_interface name="service" />
        </gpio>
        <gpio name="setting_signal_14">
            <command_interface name="service" />
        </gpio>
        <gpio name="setting_signal_15">
            <command_interface name="service" />
        </gpio>
        <gpio name="setting_signal_16">
            <command_interface name="service" />
        </gpio>
        <gpio name="setting_signal_17">
            <command_interface name="service" />
        </gpio>
        <gpio name="setting_signal_18">
            <command_interface name="service" />
        </gpio>
        <gpio name="setting_signal_19">
            <command_interface name="service" />
        </gpio>
        <gpio name="setting_signal_20">
            <command_interface name="service" />
        </gpio>
        <gpio name="setting_signal_21">
            <command_interface name="service" />
        </gpio>
        <gpio name="setting_signal_22">
            <command_interface name="service" />
        </gpio>
        <gpio name="setting_signal_23">
            <command_interface name="service" />
        </gpio>
        <gpio name="setting_signal_24">
            <command_interface name="service" />
        </gpio>
        <gpio name="setting_signal_25">
            <command_interface name="service" />
        </gpio>
        <gpio name="setting_signal_26">
            <command_interface name="service" />
        </gpio>
        <gpio name="setting_signal_27">
            <command_interface name="service" />
        </gpio>
        <gpio name="setting_signal_28">
            <command_interface name="service" />
        </gpio>
        <gpio name="setting_signal_29">
            <command_interface name="service" />
        </gpio>
        <gpio name="setting_signal_30">
            <command_interface name="service" />
        </gpio>
        <gpio name="setting_signal_31">
            <command_interface name="service" />
        </gpio>
        <gpio name="setting_signal_32">
            <command_interface name="service" />
        </gpio>
        <gpio name="pc_addrs_1">
            <command_interface name="service" />
        </gpio>
        <gpio name="pc_addrs_2">
            <command_interface name="service" />
        </gpio>
        <gpio name="pc_addrs_3">
            <command_interface name="service" />
        </gpio>
        <gpio name="pc_addrs_4">
            <command_interface name="service" />
        </gpio>
        <gpio name="l_port_no">
            <command_interface name="service" />
        </gpio>
        <gpio name="l_retry">
            <command_interface name="service" />
        </gpio>
        <gpio name="l_send_timeout">
            <command_interface name="service" />
        </gpio>
        <gpio name="l_comm_side">
            <command_interface name="service" />
        </gpio>
        <gpio name="l_mode">
            <command_interface name="service" />
        </gpio>
        <gpio name="l_kind">
            <command_interface name="service" />
        </gpio>
        <gpio name="n_open_id">
            <command_interface name="service" />
        </gpio>
        <gpio name="n_sub_id">
            <command_interface name="service" />
        </gpio>
        <gpio name="n_count_joint">
            <command_interface name="service" />
        </gpio>
        <gpio name="n_count_meca">
            <command_interface name="service" />
        </gpio>
        <gpio name="n_priority">
            <command_interface name="service" />
        </gpio>
        <gpio name="f_thereshold">
            <command_interface name="service" />
        </gpio>
        <gpio name="n_unit_id">
            <command_interface name="service" />
        </gpio>
        <gpio name="n_type">
            <command_interface name="service" />
        </gpio>
        <gpio name="n_conf">
            <command_interface name="service" />
        </gpio>
        <gpio name="f_ext_pose_no_1">
            <command_interface name="service" />
        </gpio>
        <gpio name="f_ext_pose_no_2">
            <command_interface name="service" />
        </gpio>
        <gpio name="f_ext_pose_no_3">
            <command_interface name="service" />
        </gpio>
        <gpio name="f_ext_pose_no_4">
            <command_interface name="service" />
        </gpio>
        <gpio name="f_ext_pose_no_5">
            <command_interface name="service" />
        </gpio>
        <gpio name="f_ext_pose_no_6">
            <command_interface name="service" />
        </gpio>
        <gpio name="n_ext_pos_size">
            <command_interface name="service" />
        </gpio>
        <gpio name="servomotor_state">
            <state_interface name="on_off" />
        </gpio>
    </ros2_control>

    <gazebo>
        <plugin name="gazebo_ros2_control">
            <robotNamespace>/</robotNamespace>
        </plugin>
    </gazebo>
</robot>

